Workbook

Sheet Cover sheet
B4: Company Name
B5: Address 1 | J5: Date Received: | L5: 45915
B6: Address 2 | J6: Due Date: | L6: 45917
B7: Address 3 | J7: QS Assigned: | L7: Pam
J8: Date Submitted: | L8: 45916
B9: Attention
B10: Email
B11: Contact No.
B12: Site Address:
B13: 8 Ulster Road, Blockhouse Bay | I13: Reference No. | K13: VMI-PI-6468
I14: Nimbus | K14: Nimbus Ref
B18: Ext. Walls | C18: Product description | G18: Area | H18: Ext. Walls | I18: Product description | M18: Area
B19: R2.4 90mm | C19: Premier Glasswool | G19: =ROUNDUP('Calc Sheet'!K14,0) -> 89 | H19: R2.4 90mm | I19: Premier Glasswool | M19: =ROUNDUP('Calc Sheet'!K19,0) -> 5
B20: Notes: | H20: Notes:
B21: *90/140mm wall framing | H21: *90mm wall framing
B24: Masonry Walls | C24: Product description | G24: Area | H24: G.I.W. | I24: Product description | M24: Area
B25: R1.3 50mm | C25: Premier Glasswool | G25: =ROUNDUP('Calc Sheet'!K24,0) -> 46 | H25: R1.8 75mm | I25: Premier Glasswool | M25: =ROUNDUP('Calc Sheet'!K29,0) -> 26
B26: Notes: | H26: Notes:
B27: * 45 X 45 H1.2 WITH STUDS | H27: *Garage Internal Wall
B30: Void Wall | C30: Product description | G30: Area | H30: Underfloor | I30: Product description | M30: Area
B31: R2.2 90mm | C31: Premier Glasswool | G31: =ROUNDUP('Calc Sheet'!K39,0) -> 8 | H31: R2.6 90mm | I31: Premier Polyester | M31: =ROUNDUP('Calc Sheet'!G43,0) -> 24
B32: Notes: | H32: Notes:
B33: * laid to ceiling steps
B36: Midfloor | C36: Product description | G36: Area | H36: GCFO | I36: Product description | M36: Area
B37: R3.6 155mm | C37: Premier Glasswool | G37: =ROUNDUP('Calc Sheet'!G47,0) -> 22 | H37: R3.6 155mm | I37: Premier Glasswool | M37: =ROUNDUP('Calc Sheet'!G51,0) -> 34
B38: Notes: | H38: Notes:
B39: * laid to | H39: *Garage Ceiling Floor Over
B42: Soffit | C42: Product description | G42: Area | H42: Flat Ceiling | I42: Product description | M42: Area
B43: R2.6 90mm | C43: Premier Glasswool | G43: =ROUNDUP('Calc Sheet'!G55,0) -> 9 | H43: R6.3 260mm | I43: Premier Glasswool | M43: =ROUNDUP('Calc Sheet'!G59+'Calc Sheet'!I59,0) -> 60
B44: Notes: | H44: Notes:
B45: * laid to cantilever flooring | H45: * laid to flat ceiling
B48: Garage Flat Ceiling | C48: Product description | G48: Area | H48: Raked Ceiling | I48: Product description | M48: Area
B49: R6.3 260mm | C49: Premier Glasswool | G49: =ROUNDUP('Calc Sheet'!G63,0) -> 9 | H49: R6.0 240mm | M49: =ROUNDUP('Calc Sheet'!G67,0) -> 35
B50: Notes: | H50: Notes:
B51: * laid to garage flat ceiling | H51: * 240 X 45 H1.2 RAFTERS
H52: * laid to raked ceiling
B55: General Notes:
B56: * Have allowed R2.4 90mm Premier Glasswool Insulation to External Wall and Garage External Wall in lieu of PINK BATTS" 'CLASSIC' 90MM THK x R2.4W * Have allowed R1.3 50mm Premier Glasswool Insulation to Masonry Wall in lieu of PINK BATTS" 50MM THK R1.2W * Have allowed R1.8 75mm Premier Glasswool Insulation to G.I.W in lieu of PINK BATTS" 'CLASSIC' 90MM THK x R1.8W. * Have allowed R2.2 90 mm Premier Glasswool Insulation to Void Wall. (No R- Value given). * Have allowed R2.6 90mm Premier Glasswool Insulation to Underfloor and Soffit in lieu of PINK BATTS" SNUG-FLOOR 110MM THK x R2.6 * Have allowed R3.6 155mm Premeir Glasswool Insulation to Midfloor and G.C.F.O in lieu of PINK BATTS" 'SILENCER' 150MM THK x R3.6. * Have allowed R6.3 260mm Premier Glasswoo Insulation to Flat Ceiling and Garage Flat Ceiling in lieu of PINK BATTS" 'ULTRA' 235MM THK X R6.0 * Have allowed PINK BATTS" SKILLION 240MM THK x R6.0 to Raked Ceiling. (No Premier Counterpart higher than R6.0 may fit the available ceiling space)

Sheet Sheet2
A1: Product Category | B1: Product Description / R-Value | C1: Nominal Thickness (mm) | D1: Product Format | E1: Material Weight / Density (Key Data) | F1: Source Reference
A2: Premier Polyester Acoustic Baffle Stack | B2: Premier 100% Polyester Baffle Stack | C2: 120mm (Non-compressed) | D2: Roll Form | E2: 1,000gsm; 10kg/m³ at 100mm
A3: Premier Polyester Acoustic Baffle Stack | B3: 100% Polyester Acoustic Baffle Stack | C3: 120mm | D3: Roll Form (600mm width) | E3: 1,000gsm; 8.33Kg/m³
A4: Premier Polyester Acoustic Blankets | B4: Acoustic Wall & Mid-Floor Blanket | C4: 90mm | D4: Roll Form (430mm/560mm widths) | E4: 1,100gsm; 12.2Kg/m³
A5: Premier Polyester Acoustic Blankets | B5: Acoustic IT Blanket* | C5: 90mm | D5: Roll Form (560mm width) | E5: 1,350gsm; 15.0Kg/m³
A6: Premier Polyester Acoustic Sound Blanket | B6: 50mm | C6: 50mm | D6: Roll Form (600mm width) | E6: 735gsm; 14.70Kg/m³ (GIB Approved)
A7: Premier Polyester Acoustic Sound Blanket | B7: 60mm | C7: 60mm | D7: Roll Form (600mm width) | E7: 750gsm; 12.50 Kg/m³
A8: Premier Polyester Acoustic Sound Blanket | B8: 70mm | C8: 70mm | D8: Roll Form (600mm width) | E8: 900gsm; 12.85 Kg/m³
A9: Premier Polyester Acoustic Sound Blanket | B9: 75mm | C9: 75mm | D9: Roll Form (600mm width) | E9: 1,150gsm; 15.33 Kg/m³ (GIB Approved)
A10: Premier Polyester Acoustic Sound Blanket | B10: 120mm | C10: 120mm | D10: Roll Form (600mm width) | E10: 1,680gsm; 14.00 Kg/m³
A11: Premier Polyester Acoustic Panels (PAB) | B11: PAB 35-25mm (875gsm) | C11: 25mm | D11: Panel (2400mm x 1200mm) | E11: 35Kg/m³ (NRC 0.70 est.)
A12: Premier Polyester Acoustic Panels (PAB) | B12: PAB 35-50mm (1,750gsm) | C12: 50mm | D12: Panel (2400mm x 1200mm) | E12: 35Kg/m³ (NRC 0.90 est.)
A13: Premier Polyester Acoustic Panels (PAB) | B13: PAB 20-100 mm (2,000gsm) | C13: 100mm | D13: Panel (2400mm x 1200mm) | E13: 20Kg/m³ (NRC 0.95)
... A80: Premier Glasswool Ceiling Segments | B80: R7.3 Ceiling 275mm | C80: 275mm | D80: Segments (430mm width) | E80: Density: 16Kg/m³

Sheet Calc Sheet
B5: AREA TAKE - OFF
B6: Project Name: | D6: ='Cover sheet'!B13 -> 8 Ulster Road, Blockhouse Bay
B9: OPENINGS
B10: Ext. Walls | G10: Ext. Walls
B11: Marked | C11: Height | D11: Width | E11: Area | G11: Length | H11: Height | I11: Raked | J11: Openings | K11: Area | L11: Level
B12: D01 | C12: 2.1 | D12: 0.86 | E12: =C12*D12 -> 1.806 | G12: =0.94 -> 0.94 | H12: 2.425 | J12: =E12 -> 1.806 | K12: =G12*H12+I12-J12 -> 0.4735 | L12: GF
B13: W10 | C13: 2.1 | D13: 3.6 | E13: =C13*D13 -> 7.56 | G13: =40.72+5.39 -> 46.11 | H13: 2.295 | I13: 2.91 | J13: =SUM(E13:E26) -> 20.3 | K13: =G13*H13+I13-J13 -> 88.43245 | L13: 1F
B14: W11 | C14: 0.8 | D14: 1.8 | E14: =C14*D14 -> 1.44 | G14: Total Area = | K14: =SUM(K12:K13) -> 88.90595
B15: W12 | C15: 0.9 | D15: 1.8 | E15: =C15*D15 -> 1.62
B16: W13 | C16: 1 | D16: 0.4 | E16: =C16*D16 -> 0.4 | G16: Garage Ext. Walls
B17: W14 | C17: 1 | D17: 1.6 | E17: =C17*D17 -> 1.6 | G17: Length | H17: Height | I17: Raked | J17: Openings | K17: Area | L17: Level
B18: W15 | C18: 0.8 | D18: 0.9 | E18: =C18*D18 -> 0.72 | G18: 6.09 | H18: 2.425 | J18: =E32 -> 10.08 | K18: =G18*H18+I18-J18 -> 4.68825 | L18: GF
B19: W16 | C19: 1 | D19: 0.4 | E19: =C19*D19 -> 0.4 | G19: Total Area = | K19: =SUM(K18:K18) -> 4.68825
B20: W17 | C20: 1 | D20: 1.6 | E20: =C20*D20 -> 1.6
B21: W18 | C21: 0.8 | D21: 0.6 | E21: =C21*D21 -> 0.48 | G21: Masonry Walls
B22: W19 | C22: 1 | D22: 0.8 | E22: =C22*D22 -> 0.8 | G22: Length | H22: Height | I22: Raked | J22: Openings | K22: Area | L22: Level
B23: W20 | C23: 0.4 | D23: 1.6 | E23: =C23*D23 -> 0.64 | G23: 19.49 | H23: 2.425 | J23: =E39 -> 1.92 | K23: =G23*H23+I23-J23 -> 45.34325 | L23: GF
B24: W21 | C24: 0.4 | D24: 1.2 | E24: =C24*D24 -> 0.48 | G24: Total Area = | K24: =SUM(K23:K23) -> 45.34325
B25: W22 | C25: 0.8 | D25: 1.2 | E25: =C25*D25 -> 0.96
B26: W23 | C26: 0.8 | D26: 2 | E26: =C26*D26 -> 1.6 | G26: G.I.W.
B27: Total Area= | E27: =SUM(E12:E26) -> 22.106 | G27: Length | H27: Height | I27: Raked | J27: Openings | K27: Area | L27: Level
G28: 12.56 | H28: 2.425 | J28: =E46 -> 4.6134 | K28: =G28*H28+I28-J28 -> 25.8446 | L28: GF
B29: Garage Ext. Walls | G29: Total Area = | K29: =SUM(K28:K28) -> 25.8446
B30: Marked | C30: Height | D30: Width | E30: Area
B31: D02 | C31: 2.1 | D31: 4.8 | E31: =C31*D31 -> 10.08 | G31: Void Wall
B32: Total Area= | E32: =SUM(E31:E31) -> 10.08 | G32: Length | H32: Height | I32: Raked | J32: Openings | K32: Area | L32: Level
G33: 0.692 | H33: 1.01 | I33: 2.91 | K33: =G33*H33+I33-J33 -> 3.60892 | L33: 1F
B34: Masonry Walls | G34: 0.692 | H34: 1.24 | K34: =G34*H34+I34-J34 -> 0.85808 | L34: 1F
B35: Marked | C35: Height | D35: Width | E35: Area | G35: 0.692 | H35: =(1.01+1.24)/2 -> 1.125 | K35: =G35*H35+I35-J35 -> 0.7785 | L35: 1F
B36: W04 | C36: 0.6 | D36: 1 | E36: =C36*D36 -> 0.6 | G36: 0.692 | H36: 1.26 | K36: =G36*H36+I36-J36 -> 0.87192 | L36: 1F
B37: W03 | C37: 0.6 | D37: 1 | E37: =C37*D37 -> 0.6 | G37: 0.692 | H37: 0.88 | K37: =G37*H37+I37-J37 -> 0.60896 | L37: 1F
B38: W02 | C38: 0.6 | D38: 1.2 | E38: =C38*D38 -> 0.72 | G38: 0.895 | H38: =(1.26+0.88)/2 -> 1.07 | K38: =G38*H38+I38-J38 -> 0.95765 | L38: 1F
B39: Total Area= | E39: =SUM(E36:E38) -> 1.92 | G39: Total Area = | K39: =SUM(K33:K38) -> 7.68403
B41: G.I.W. | G41: Underfloor
B42: Marked | C42: Height | D42: Width | E42: Area | G42: Area | H42: Level | I42: Area | J42: Level | K42: Area | L42: Level
C43: 1.98 | D43: 0.76 | E43: =C43*D43 -> 1.5048 | G43: 23.44 | H43: GF
C44: 1.98 | D44: 0.76 | E44: =C44*D44 -> 1.5048
C45: 1.98 | D45: 0.81 | E45: =C45*D45 -> 1.6038 | G45: Midfloor
B46: Total Area= | E46: =SUM(E43:E45) -> 4.6134 | G46: Area | H46: Level | I46: Area | J46: Level | K46: Area | L46: Level
G47: =18.19+3.59 -> 21.78 | H47: GF
...

Sheet Sheet1
B2: Ext. Walls | C2: Product description | G2: Area | H2: Masonry Walls | I2: Product description | M2: Area | O2: Ext. Walls
B3: R2.2 90mm | C3: Premier Glasswool | G3: =ROUNDUP(,0) -> 0 | H3: R1.3 45mm | I3: Premier Glasswool | M3: =ROUNDUP(,0) -> 0 | O3: Length | P3: Height | Q3: Raked | R3: Openings | S3: Area | T3: Level
B4: Notes: | H4: Notes: | S4: =O4*P4+Q4-R4 -> 0 | T4: GF
S5: =O5*P5+Q5-R5 -> 0 | T5: 1F
S6: =O6*P6+Q6-R6 -> 0 | T6: 2F
O7: Total Area = | S7: =SUM(S4:S6) -> 0
B8: G.I.W. | C8: Product description | G8: Area | H8: Int. Wall | I8: Product description | M8: Area
B9: R2.2 90mm | C9: Premier Glasswool | G9: =ROUNDUP(,0) -> 0 | H9: R2.2 90mm | I9: Premier Glasswool | M9: =ROUNDUP(,0) -> 0 | O9: Masonry Walls
B10: Notes: | H10: Notes: | O10: Length | P10: Height | Q10: Raked | R10: Openings | S10: Area | T10: Level
B11: *Garage Internal Wall | S11: =O11*P11+Q11-R11 -> 0
S12: =O12*P12+Q12-R12 -> 0
S13: =O13*P13+Q13-R13 -> 0
B14: Underfloor | C14: Product description | G14: Area | H14: Midfloor | I14: Product description | M14: Area | O14: Total Area = | S14: =SUM(S11:S13) -> 0
B15: R1.5 100mm | C15: Premier Polyester | G15: =ROUNDUP(,0) -> 0 | H15: R1.8 75mm | I15: Premier Glasswool | M15: =ROUNDUP(,0) -> 0
B16: Notes: | H16: Notes: | O16: G.I.W.
O17: Length | P17: Height | Q17: Raked | R17: Openings | S17: Area | T17: Level
S18: =O18*P18+Q18-R18 -> 0
O19: Total Area = | S19: =SUM(S18:S18) -> 0
B20: Soffit | C20: Product description | G20: Area | H20: Flat Ceiling | I20: Product description | M20: Area
B21: R1.8 75mm | C21: Premier Glasswool | G21: =ROUNDUP(,0) -> 0 | H21: R3.3 145mm | I21: Premier Glasswool | M21: =ROUNDUP(,0) -> 0 | O21: Int. Wall
B22: Notes: | H22: Notes: | O22: Length | P22: Height | Q22: Raked | R22: Openings | S22: Area | T22: Level
S23: =O23*P23+Q23-R23 -> 0
S24: =O24*P24+Q24-R24 -> 0
S25: =O25*P25+Q25-R25 -> 0
B26: Raked Ceiling | C26: Product description | G26: Area | H26: GCFO | I26: Product description | M26: Area | O26: Total Area = | S26: =SUM(S23:S25) -> 0
B27: R3.3 145mm | C27: Premier Glasswool | G27: =ROUNDUP(,0) -> 0 | H27: R1.8 75mm | I27: Premier Glasswool | M27: =ROUNDUP(,0) -> 0
B28: Notes: | H28: Notes: | O28: Void Wall
H29: *Garage Ceiling Floor Over | O29: Length | P29: Height | Q29: Raked | R29: Openings | S29: Area | T29: Level
S30: =O30*P30+Q30-R30 -> 0
S31: =O31*P31+Q31-R31 -> 0
B32: I.T. Walls | C32: Product description | G32: Area | H32: Void Wall | I32: Product description | M32: Area | S32: =O32*P32+Q32-R32 -> 0
B33: R2.2 90mm | G33: =ROUNDUP(,0) -> 0 | H33: R2.2 90mm | I33: Premier Glasswool | M33: =ROUNDUP(,0) -> 0 | O33: Total Area = | S33: =SUM(S30:S32) -> 0
B34: Notes: | H34: Notes:
B35: *Intertenancy Wall | O35: I.T. Walls
O36: Length | P36: Height | Q36: Raked | R36: Openings | S36: Area | T36: Level
B37: Wing Wall | C37: Product description | G37: Area | S37: =O37*P37+Q37-R37 -> 0
B38: R2.2 90mm | G38: =ROUNDUP(,0) -> 0 | S38: =O38*P38+Q38-R38 -> 0
B39: Notes: | O39: Total Area = | S39: =SUM(S37:S38) -> 0
O41: Wing Wall
O42: Length | P42: Height | Q42: Raked | R42: Openings | S42: Area | T42: Level
...
